Traceback (most recent call last):
  File "/home/pi/Code/BLE-MESH/gateway/app/app.py", line 37, in <module>
    mqtt = Mqtt(app)
           ^^^^^^^^^
  File "/home/pi/Code/BLE-MESH/gateway/myvenv/lib/python3.11/site-packages/flask_mqtt/__init__.py", line 105, in __init__
    self.init_app(app, self.config_prefix)
  File "/home/pi/Code/BLE-MESH/gateway/myvenv/lib/python3.11/site-packages/flask_mqtt/__init__.py", line 188, in init_app
    self._connect()
  File "/home/pi/Code/BLE-MESH/gateway/myvenv/lib/python3.11/site-packages/flask_mqtt/__init__.py", line 214, in _connect
    res = self.client.connect(
          ^^^^^^^^^^^^^^^^^^^^
  File "/home/pi/Code/BLE-MESH/gateway/myvenv/lib/python3.11/site-packages/paho/mqtt/client.py", line 914, in connect
    return self.reconnect()
           ^^^^^^^^^^^^^^^^
  File "/home/pi/Code/BLE-MESH/gateway/myvenv/lib/python3.11/site-packages/paho/mqtt/client.py", line 1044, in reconnect
    sock = self._create_socket_connection()
           ^^^^^^^^^^^^^^^^^^^^^^^^^^^^^^^^
  File "/home/pi/Code/BLE-MESH/gateway/myvenv/lib/python3.11/site-packages/paho/mqtt/client.py", line 3685, in _create_socket_connection
    return socket.create_connection(addr, timeout=self._connect_timeout, source_address=source)
           ^^^^^^^^^^^^^^^^^^^^^^^^^^^^^^^^^^^^^^^^^^^^^^^^^^^^^^^^^^^^^^^^^^^^^^^^^^^^^^^^^^^^
  File "/usr/lib/python3.11/socket.py", line 851, in create_connection
    raise exceptions[0]
  File "/usr/lib/python3.11/socket.py", line 836, in create_connection
    sock.connect(sa)
TimeoutError: timed out
Traceback (most recent call last):
  File "/home/pi/Code/BLE-MESH/gateway/app/app.py", line 37, in <module>
    mqtt = Mqtt(app)
           ^^^^^^^^^
  File "/home/pi/Code/BLE-MESH/gateway/myvenv/lib/python3.11/site-packages/flask_mqtt/__init__.py", line 105, in __init__
    self.init_app(app, self.config_prefix)
  File "/home/pi/Code/BLE-MESH/gateway/myvenv/lib/python3.11/site-packages/flask_mqtt/__init__.py", line 188, in init_app
    self._connect()
  File "/home/pi/Code/BLE-MESH/gateway/myvenv/lib/python3.11/site-packages/flask_mqtt/__init__.py", line 214, in _connect
    res = self.client.connect(
          ^^^^^^^^^^^^^^^^^^^^
  File "/home/pi/Code/BLE-MESH/gateway/myvenv/lib/python3.11/site-packages/paho/mqtt/client.py", line 914, in connect
    return self.reconnect()
           ^^^^^^^^^^^^^^^^
  File "/home/pi/Code/BLE-MESH/gateway/myvenv/lib/python3.11/site-packages/paho/mqtt/client.py", line 1044, in reconnect
    sock = self._create_socket_connection()
           ^^^^^^^^^^^^^^^^^^^^^^^^^^^^^^^^
  File "/home/pi/Code/BLE-MESH/gateway/myvenv/lib/python3.11/site-packages/paho/mqtt/client.py", line 3685, in _create_socket_connection
    return socket.create_connection(addr, timeout=self._connect_timeout, source_address=source)
           ^^^^^^^^^^^^^^^^^^^^^^^^^^^^^^^^^^^^^^^^^^^^^^^^^^^^^^^^^^^^^^^^^^^^^^^^^^^^^^^^^^^^
  File "/usr/lib/python3.11/socket.py", line 851, in create_connection
    raise exceptions[0]
  File "/usr/lib/python3.11/socket.py", line 836, in create_connection
    sock.connect(sa)
TimeoutError: timed out
Traceback (most recent call last):
  File "/home/pi/Code/BLE-MESH/gateway/app/app.py", line 37, in <module>
    mqtt = Mqtt(app)
           ^^^^^^^^^
  File "/home/pi/Code/BLE-MESH/gateway/myvenv/lib/python3.11/site-packages/flask_mqtt/__init__.py", line 105, in __init__
    self.init_app(app, self.config_prefix)
  File "/home/pi/Code/BLE-MESH/gateway/myvenv/lib/python3.11/site-packages/flask_mqtt/__init__.py", line 188, in init_app
    self._connect()
  File "/home/pi/Code/BLE-MESH/gateway/myvenv/lib/python3.11/site-packages/flask_mqtt/__init__.py", line 214, in _connect
    res = self.client.connect(
          ^^^^^^^^^^^^^^^^^^^^
  File "/home/pi/Code/BLE-MESH/gateway/myvenv/lib/python3.11/site-packages/paho/mqtt/client.py", line 914, in connect
    return self.reconnect()
           ^^^^^^^^^^^^^^^^
  File "/home/pi/Code/BLE-MESH/gateway/myvenv/lib/python3.11/site-packages/paho/mqtt/client.py", line 1044, in reconnect
    sock = self._create_socket_connection()
           ^^^^^^^^^^^^^^^^^^^^^^^^^^^^^^^^
  File "/home/pi/Code/BLE-MESH/gateway/myvenv/lib/python3.11/site-packages/paho/mqtt/client.py", line 3685, in _create_socket_connection
    return socket.create_connection(addr, timeout=self._connect_timeout, source_address=source)
           ^^^^^^^^^^^^^^^^^^^^^^^^^^^^^^^^^^^^^^^^^^^^^^^^^^^^^^^^^^^^^^^^^^^^^^^^^^^^^^^^^^^^
  File "/usr/lib/python3.11/socket.py", line 851, in create_connection
    raise exceptions[0]
  File "/usr/lib/python3.11/socket.py", line 836, in create_connection
    sock.connect(sa)
TimeoutError: timed out
Traceback (most recent call last):
  File "/home/pi/Code/BLE-MESH/gateway/app/app.py", line 37, in <module>
    mqtt = Mqtt(app)
           ^^^^^^^^^
  File "/home/pi/Code/BLE-MESH/gateway/myvenv/lib/python3.11/site-packages/flask_mqtt/__init__.py", line 105, in __init__
    self.init_app(app, self.config_prefix)
  File "/home/pi/Code/BLE-MESH/gateway/myvenv/lib/python3.11/site-packages/flask_mqtt/__init__.py", line 188, in init_app
    self._connect()
  File "/home/pi/Code/BLE-MESH/gateway/myvenv/lib/python3.11/site-packages/flask_mqtt/__init__.py", line 214, in _connect
    res = self.client.connect(
          ^^^^^^^^^^^^^^^^^^^^
  File "/home/pi/Code/BLE-MESH/gateway/myvenv/lib/python3.11/site-packages/paho/mqtt/client.py", line 914, in connect
    return self.reconnect()
           ^^^^^^^^^^^^^^^^
  File "/home/pi/Code/BLE-MESH/gateway/myvenv/lib/python3.11/site-packages/paho/mqtt/client.py", line 1044, in reconnect
    sock = self._create_socket_connection()
           ^^^^^^^^^^^^^^^^^^^^^^^^^^^^^^^^
  File "/home/pi/Code/BLE-MESH/gateway/myvenv/lib/python3.11/site-packages/paho/mqtt/client.py", line 3685, in _create_socket_connection
    return socket.create_connection(addr, timeout=self._connect_timeout, source_address=source)
           ^^^^^^^^^^^^^^^^^^^^^^^^^^^^^^^^^^^^^^^^^^^^^^^^^^^^^^^^^^^^^^^^^^^^^^^^^^^^^^^^^^^^
  File "/usr/lib/python3.11/socket.py", line 851, in create_connection
    raise exceptions[0]
  File "/usr/lib/python3.11/socket.py", line 836, in create_connection
    sock.connect(sa)
TimeoutError: timed out
Traceback (most recent call last):
  File "/home/pi/Code/BLE-MESH/gateway/app/app.py", line 37, in <module>
    mqtt = Mqtt(app)
           ^^^^^^^^^
  File "/home/pi/Code/BLE-MESH/gateway/myvenv/lib/python3.11/site-packages/flask_mqtt/__init__.py", line 105, in __init__
    self.init_app(app, self.config_prefix)
  File "/home/pi/Code/BLE-MESH/gateway/myvenv/lib/python3.11/site-packages/flask_mqtt/__init__.py", line 188, in init_app
    self._connect()
  File "/home/pi/Code/BLE-MESH/gateway/myvenv/lib/python3.11/site-packages/flask_mqtt/__init__.py", line 214, in _connect
    res = self.client.connect(
          ^^^^^^^^^^^^^^^^^^^^
  File "/home/pi/Code/BLE-MESH/gateway/myvenv/lib/python3.11/site-packages/paho/mqtt/client.py", line 914, in connect
    return self.reconnect()
           ^^^^^^^^^^^^^^^^
  File "/home/pi/Code/BLE-MESH/gateway/myvenv/lib/python3.11/site-packages/paho/mqtt/client.py", line 1044, in reconnect
    sock = self._create_socket_connection()
           ^^^^^^^^^^^^^^^^^^^^^^^^^^^^^^^^
  File "/home/pi/Code/BLE-MESH/gateway/myvenv/lib/python3.11/site-packages/paho/mqtt/client.py", line 3685, in _create_socket_connection
    return socket.create_connection(addr, timeout=self._connect_timeout, source_address=source)
           ^^^^^^^^^^^^^^^^^^^^^^^^^^^^^^^^^^^^^^^^^^^^^^^^^^^^^^^^^^^^^^^^^^^^^^^^^^^^^^^^^^^^
  File "/usr/lib/python3.11/socket.py", line 851, in create_connection
    raise exceptions[0]
  File "/usr/lib/python3.11/socket.py", line 836, in create_connection
    sock.connect(sa)
TimeoutError: timed out
Traceback (most recent call last):
  File "/home/pi/Code/BLE-MESH/gateway/app/app.py", line 37, in <module>
    mqtt = Mqtt(app)
           ^^^^^^^^^
  File "/home/pi/Code/BLE-MESH/gateway/myvenv/lib/python3.11/site-packages/flask_mqtt/__init__.py", line 105, in __init__
    self.init_app(app, self.config_prefix)
  File "/home/pi/Code/BLE-MESH/gateway/myvenv/lib/python3.11/site-packages/flask_mqtt/__init__.py", line 188, in init_app
    self._connect()
  File "/home/pi/Code/BLE-MESH/gateway/myvenv/lib/python3.11/site-packages/flask_mqtt/__init__.py", line 214, in _connect
    res = self.client.connect(
          ^^^^^^^^^^^^^^^^^^^^
  File "/home/pi/Code/BLE-MESH/gateway/myvenv/lib/python3.11/site-packages/paho/mqtt/client.py", line 914, in connect
    return self.reconnect()
           ^^^^^^^^^^^^^^^^
  File "/home/pi/Code/BLE-MESH/gateway/myvenv/lib/python3.11/site-packages/paho/mqtt/client.py", line 1044, in reconnect
    sock = self._create_socket_connection()
           ^^^^^^^^^^^^^^^^^^^^^^^^^^^^^^^^
  File "/home/pi/Code/BLE-MESH/gateway/myvenv/lib/python3.11/site-packages/paho/mqtt/client.py", line 3685, in _create_socket_connection
    return socket.create_connection(addr, timeout=self._connect_timeout, source_address=source)
           ^^^^^^^^^^^^^^^^^^^^^^^^^^^^^^^^^^^^^^^^^^^^^^^^^^^^^^^^^^^^^^^^^^^^^^^^^^^^^^^^^^^^
  File "/usr/lib/python3.11/socket.py", line 851, in create_connection
    raise exceptions[0]
  File "/usr/lib/python3.11/socket.py", line 836, in create_connection
    sock.connect(sa)
TimeoutError: timed out
Traceback (most recent call last):
  File "/home/pi/Code/BLE-MESH/gateway/app/app.py", line 37, in <module>
    mqtt = Mqtt(app)
           ^^^^^^^^^
  File "/home/pi/Code/BLE-MESH/gateway/myvenv/lib/python3.11/site-packages/flask_mqtt/__init__.py", line 105, in __init__
    self.init_app(app, self.config_prefix)
  File "/home/pi/Code/BLE-MESH/gateway/myvenv/lib/python3.11/site-packages/flask_mqtt/__init__.py", line 188, in init_app
    self._connect()
  File "/home/pi/Code/BLE-MESH/gateway/myvenv/lib/python3.11/site-packages/flask_mqtt/__init__.py", line 214, in _connect
    res = self.client.connect(
          ^^^^^^^^^^^^^^^^^^^^
  File "/home/pi/Code/BLE-MESH/gateway/myvenv/lib/python3.11/site-packages/paho/mqtt/client.py", line 914, in connect
    return self.reconnect()
           ^^^^^^^^^^^^^^^^
  File "/home/pi/Code/BLE-MESH/gateway/myvenv/lib/python3.11/site-packages/paho/mqtt/client.py", line 1044, in reconnect
    sock = self._create_socket_connection()
           ^^^^^^^^^^^^^^^^^^^^^^^^^^^^^^^^
  File "/home/pi/Code/BLE-MESH/gateway/myvenv/lib/python3.11/site-packages/paho/mqtt/client.py", line 3685, in _create_socket_connection
    return socket.create_connection(addr, timeout=self._connect_timeout, source_address=source)
           ^^^^^^^^^^^^^^^^^^^^^^^^^^^^^^^^^^^^^^^^^^^^^^^^^^^^^^^^^^^^^^^^^^^^^^^^^^^^^^^^^^^^
  File "/usr/lib/python3.11/socket.py", line 851, in create_connection
    raise exceptions[0]
  File "/usr/lib/python3.11/socket.py", line 836, in create_connection
    sock.connect(sa)
TimeoutError: timed out
Traceback (most recent call last):
  File "/home/pi/Code/BLE-MESH/gateway/app/app.py", line 37, in <module>
    mqtt = Mqtt(app)
           ^^^^^^^^^
  File "/home/pi/Code/BLE-MESH/gateway/myvenv/lib/python3.11/site-packages/flask_mqtt/__init__.py", line 105, in __init__
    self.init_app(app, self.config_prefix)
  File "/home/pi/Code/BLE-MESH/gateway/myvenv/lib/python3.11/site-packages/flask_mqtt/__init__.py", line 188, in init_app
    self._connect()
  File "/home/pi/Code/BLE-MESH/gateway/myvenv/lib/python3.11/site-packages/flask_mqtt/__init__.py", line 214, in _connect
    res = self.client.connect(
          ^^^^^^^^^^^^^^^^^^^^
  File "/home/pi/Code/BLE-MESH/gateway/myvenv/lib/python3.11/site-packages/paho/mqtt/client.py", line 914, in connect
    return self.reconnect()
           ^^^^^^^^^^^^^^^^
  File "/home/pi/Code/BLE-MESH/gateway/myvenv/lib/python3.11/site-packages/paho/mqtt/client.py", line 1044, in reconnect
    sock = self._create_socket_connection()
           ^^^^^^^^^^^^^^^^^^^^^^^^^^^^^^^^
  File "/home/pi/Code/BLE-MESH/gateway/myvenv/lib/python3.11/site-packages/paho/mqtt/client.py", line 3685, in _create_socket_connection
    return socket.create_connection(addr, timeout=self._connect_timeout, source_address=source)
           ^^^^^^^^^^^^^^^^^^^^^^^^^^^^^^^^^^^^^^^^^^^^^^^^^^^^^^^^^^^^^^^^^^^^^^^^^^^^^^^^^^^^
  File "/usr/lib/python3.11/socket.py", line 851, in create_connection
    raise exceptions[0]
  File "/usr/lib/python3.11/socket.py", line 836, in create_connection
    sock.connect(sa)
TimeoutError: timed out
Traceback (most recent call last):
  File "/home/pi/Code/BLE-MESH/gateway/app/app.py", line 37, in <module>
    mqtt = Mqtt(app)
           ^^^^^^^^^
  File "/home/pi/Code/BLE-MESH/gateway/myvenv/lib/python3.11/site-packages/flask_mqtt/__init__.py", line 105, in __init__
    self.init_app(app, self.config_prefix)
  File "/home/pi/Code/BLE-MESH/gateway/myvenv/lib/python3.11/site-packages/flask_mqtt/__init__.py", line 188, in init_app
    self._connect()
  File "/home/pi/Code/BLE-MESH/gateway/myvenv/lib/python3.11/site-packages/flask_mqtt/__init__.py", line 214, in _connect
    res = self.client.connect(
          ^^^^^^^^^^^^^^^^^^^^
  File "/home/pi/Code/BLE-MESH/gateway/myvenv/lib/python3.11/site-packages/paho/mqtt/client.py", line 914, in connect
    return self.reconnect()
           ^^^^^^^^^^^^^^^^
  File "/home/pi/Code/BLE-MESH/gateway/myvenv/lib/python3.11/site-packages/paho/mqtt/client.py", line 1044, in reconnect
    sock = self._create_socket_connection()
           ^^^^^^^^^^^^^^^^^^^^^^^^^^^^^^^^
  File "/home/pi/Code/BLE-MESH/gateway/myvenv/lib/python3.11/site-packages/paho/mqtt/client.py", line 3685, in _create_socket_connection
    return socket.create_connection(addr, timeout=self._connect_timeout, source_address=source)
           ^^^^^^^^^^^^^^^^^^^^^^^^^^^^^^^^^^^^^^^^^^^^^^^^^^^^^^^^^^^^^^^^^^^^^^^^^^^^^^^^^^^^
  File "/usr/lib/python3.11/socket.py", line 851, in create_connection
    raise exceptions[0]
  File "/usr/lib/python3.11/socket.py", line 836, in create_connection
    sock.connect(sa)
TimeoutError: timed out
Traceback (most recent call last):
  File "/home/pi/Code/BLE-MESH/gateway/app/app.py", line 37, in <module>
    mqtt = Mqtt(app)
           ^^^^^^^^^
  File "/home/pi/Code/BLE-MESH/gateway/myvenv/lib/python3.11/site-packages/flask_mqtt/__init__.py", line 105, in __init__
    self.init_app(app, self.config_prefix)
  File "/home/pi/Code/BLE-MESH/gateway/myvenv/lib/python3.11/site-packages/flask_mqtt/__init__.py", line 188, in init_app
    self._connect()
  File "/home/pi/Code/BLE-MESH/gateway/myvenv/lib/python3.11/site-packages/flask_mqtt/__init__.py", line 214, in _connect
    res = self.client.connect(
          ^^^^^^^^^^^^^^^^^^^^
  File "/home/pi/Code/BLE-MESH/gateway/myvenv/lib/python3.11/site-packages/paho/mqtt/client.py", line 914, in connect
    return self.reconnect()
           ^^^^^^^^^^^^^^^^
  File "/home/pi/Code/BLE-MESH/gateway/myvenv/lib/python3.11/site-packages/paho/mqtt/client.py", line 1044, in reconnect
    sock = self._create_socket_connection()
           ^^^^^^^^^^^^^^^^^^^^^^^^^^^^^^^^
  File "/home/pi/Code/BLE-MESH/gateway/myvenv/lib/python3.11/site-packages/paho/mqtt/client.py", line 3685, in _create_socket_connection
    return socket.create_connection(addr, timeout=self._connect_timeout, source_address=source)
           ^^^^^^^^^^^^^^^^^^^^^^^^^^^^^^^^^^^^^^^^^^^^^^^^^^^^^^^^^^^^^^^^^^^^^^^^^^^^^^^^^^^^
  File "/usr/lib/python3.11/socket.py", line 851, in create_connection
    raise exceptions[0]
  File "/usr/lib/python3.11/socket.py", line 836, in create_connection
    sock.connect(sa)
TimeoutError: timed out
Werkzeug appears to be used in a production deployment. Consider switching to a production web server instead.
 * Serving Flask app 'app'
 * Debug mode: off
WARNING: This is a development server. Do not use it in a production deployment. Use a production WSGI server instead.
 * Running on all addresses (0.0.0.0)
 * Running on http://127.0.0.1:5000
 * Running on http://192.168.1.18:5000
Press CTRL+C to quit
